<?xml version="1.0"?>
<robot name="rb1_robot" xmlns:xacro="http://www.ros.org/wiki/xacro">


    <!-- Include Gazebo-specific properties -->
    <xacro:include filename="$(find my_rb1_description)/urdf/my_rb1_robot.gazebo" />

    <!--All units in m-kg-s-radians unit system -->
    <xacro:property name="PI" value="3.1415926535897931" />

    <!-- Main Body-base -->
    <xacro:property name="base_height" value="0.30" /> 
    <xacro:property name="base_radius" value="0.25" />
    <xacro:property name="base_mass" value="19" />

    <!-- Wheels -->
    <xacro:property name="wheel_radius" value="0.025" />
    <xacro:property name="wheel_height" value="0.05" />
    <xacro:property name="wheel_mass" value="1.0" />

    <!-- Casters -->
    <xacro:property name="caster_radius" value="0.025" />
    <xacro:property name="caster_mass" value="1.5" />

    <!-- Laser -->
    <xacro:property name="laser_radius" value="0.03" />
    <xacro:property name="laser_height" value="0.04" />
    <xacro:property name="laser_mass" value="1.0" />

    <!-- BASE-FOOTPRINT -->
    <!-- base_footprint is a fictitious link(frame) that is on the ground right below base_link origin -->
    <link name="base_footprint">
        <inertial>
            <mass value="0.0001" />
            <origin xyz="0 0 0" />
            <inertia ixx="0.0001" ixy="0.0" ixz="0.0"
                     iyy="0.0001" iyz="0.0" 
                     izz="0.0001" />
        </inertial>
    </link>

    <!-- BASE-FOOTPRINT TO BASE-LINK JOINT -->
    <joint name="base_footprint_joint" type="fixed">
        <origin xyz="0 0 0.15" rpy="0 0 0" />
        <parent link="base_footprint"/>
        <child link="base_link" />
    </joint>

    <!-- BASE-LINK -->
    <!--Actual body/chassis of the robot-->
    <link name="base_link">
        <inertial>
            <mass value="${base_mass}" />
            <origin xyz="0 0 0" />
            <!--The 3x3 rotational inertia matrix. -->
            <inertia ixx="0.4277" ixy="0" ixz="0" iyy="0.4277" iyz="0" izz="0.5781"/>
        </inertial>
        
        <visual>
            <origin xyz="0 0 0" rpy="0 0 0" />
            <geometry>
                <cylinder radius="${base_radius}" length="${base_height}"/>
            </geometry>
            <material name="Black">
                <color rgba="0.0 0.0 0.0 1.0"/>
            </material>
        </visual>
        
        <collision>
            <origin xyz="0 0 0" rpy="0 0 0" />
            <geometry>
                <cylinder radius="${base_radius}" length="${base_height}"/>
            </geometry>
        </collision>
    </link>

    <!-- LEFT WHEEL -->
    <link name="left_wheel">
        <inertial>
            <mass value="${wheel_mass}" />
            <origin xyz="0 0 0" rpy="0 0 0" />
            <inertia ixx="0.000365" ixy="0" ixz="0" iyy="0.000365" iyz="0" izz="0.0003125"/>
        </inertial>
        
        <visual>
            <origin xyz="0 0 0" rpy="${PI/2} 0 0" />
            <geometry>
                <cylinder radius="${wheel_radius}" length="${wheel_height}"/>
            </geometry>
            <material name="DarkGray">
                <color rgba="0.4 0.4 0.4 1.0"/>
            </material>
        </visual>
        
        <collision>
            <origin xyz="0 0 0" rpy="${PI/2} 0 0" />
            <geometry>
                <cylinder radius="${wheel_radius}" length="${wheel_height}"/>
            </geometry>
        </collision>
    </link>

    <joint name="left_wheel_joint" type="continuous">
        <origin xyz="0.0 0.2 -0.15" rpy="0 0 0" />
        <parent link="base_link"/>
        <child link="left_wheel" />
        <axis xyz="0 1 0" />
    </joint>

    <!-- RIGHT WHEEL -->
    <link name="right_wheel">
        <inertial>
            <mass value="${wheel_mass}" />
            <origin xyz="0 0 0" rpy="0 0 0" />
            <inertia ixx="0.000365" ixy="0" ixz="0" iyy="0.000365" iyz="0" izz="0.0003125"/>
        </inertial>
        
        <visual>
            <origin xyz="0 0 0" rpy="${PI/2} 0 0" />
            <geometry>
                <cylinder radius="${wheel_radius}" length="${wheel_height}"/>
            </geometry>
            <material name="DarkGray">
                <color rgba="0.4 0.4 0.4 1.0"/>
            </material>
        </visual>
        
        <collision>
            <origin xyz="0 0 0" rpy="${PI/2} 0 0" />
            <geometry>
                <cylinder radius="${wheel_radius}" length="${wheel_height}"/>
            </geometry>
        </collision>
    </link>

    <joint name="right_wheel_joint" type="continuous">
        <origin xyz="0.0 -0.2 -0.15" rpy="0 0 0" />
        <parent link="base_link"/>
        <child link="right_wheel" />
        <axis xyz="0 1 0" />
    </joint>

    <!-- FRONT CASTER -->
    <link name="front_caster">
        <inertial>
            <mass value="${caster_mass}" />
            <origin xyz="0 0 0" rpy="0 0 0" />
            <inertia ixx="0.000375" ixy="0" ixz="0" iyy="0.000375" iyz="0" izz="0.000375"/>
        </inertial>
        
        <visual>
            <origin xyz="0 0 0" rpy="0 0 0" />
            <geometry>
                <sphere radius="${caster_radius}"/>
            </geometry>
            <material name="White">
                <color rgba="1.0 1.0 1.0 1.0"/>
            </material>
        </visual>
        
        <collision>
            <origin xyz="0 0 0" rpy="0 0 0" />
            <geometry>
                <sphere radius="${caster_radius}"/>
            </geometry>
            <surface>
                <friction>
                    <ode>
                        <mu>0.0</mu>
                        <mu2>0.0</mu2>
                    </ode>
                </friction>
            </surface>
        </collision>
    </link>

    <joint name="front_caster_joint" type="fixed">
        <origin xyz="-0.1 0.0 -0.15" rpy="0 0 0" />
        <parent link="base_link"/>
        <child link="front_caster" />
    </joint>

    <!-- BACK CASTER -->
    <link name="back_caster">
        <inertial>
            <mass value="${caster_mass}" />
            <origin xyz="0 0 0" rpy="0 0 0" />
            <inertia ixx="0.000375" ixy="0" ixz="0" iyy="0.000375" iyz="0" izz="0.000375"/>
        </inertial>
        
        <visual>
            <origin xyz="0 0 0" rpy="0 0 0" />
            <geometry>
                <sphere radius="${caster_radius}"/>
            </geometry>
            <material name="White">
                <color rgba="1.0 1.0 1.0 1.0"/>
            </material>
        </visual>
        
        <collision>
            <origin xyz="0 0 0" rpy="0 0 0" />
            <geometry>
                <sphere radius="${caster_radius}"/>
            </geometry>
            <surface>
                <friction>
                    <ode>
                        <mu>0.0</mu>
                        <mu2>0.0</mu2>
                    </ode>
                </friction>
            </surface>
        </collision>
    </link>

    <joint name="back_caster_joint" type="fixed">
        <origin xyz="0.1 0.0 -0.15" rpy="0 0 0" />
        <parent link="base_link"/>
        <child link="back_caster" />
    </joint>

    <!-- LASER LINK -->
    <link name="front_laser">
        <inertial>
            <mass value="${laser_mass}" />
            <origin xyz="0 0 0" rpy="0 0 0" />
            <inertia ixx="0.000308" ixy="0" ixz="0" iyy="0.000308" iyz="0" izz="0.00045"/>
        </inertial>
        
        <visual>
            <origin xyz="0 0 0" rpy="0 0 0" />
            <geometry>
                <cylinder radius="${laser_radius}" length="${laser_height}"/>
            </geometry>
            <material name="Red">
                <color rgba="1.0 0.0 0.0 1.0"/>
            </material>
        </visual>
        
        <collision>
            <origin xyz="0 0 0" rpy="0 0 0" />
            <geometry>
                <cylinder radius="${laser_radius}" length="${laser_height}"/>
            </geometry>
        </collision>
    </link>

    <!-- LASER JOINT -->
    <joint name="laser_joint" type="fixed">
        <origin xyz="0.25 0.0 0.075" rpy="${PI} 0 0" />
        <parent link="base_link"/>
        <child link="front_laser" />
    </joint>


</robot>